Workbook

Sheet Sales_Transactions
A1: Order ID | B1: Order Date | C1: Customer ID | D1: Product ID | E1: Salesperson ID | F1: Quantity | G1: Discount % | H1: Shipping Mode | I1: Payment Mode | J1: Order Status
A2: ORD-100001 | B2: 46152 | C2: CUST-0082 | D2: PRD-0014 | E2: EMP-014 | F2: 10 | G2: 0.2 | H2: Standard | I2: COD | J2: Processing
A3: ORD-100002 | B3: 45791 | C3: CUST-0314 | D3: PRD-0004 | E3: EMP-022 | F3: 8 | G3: 0.2 | H3: Standard | I3: COD | J3: Delivered
A4: ORD-100003 | B4: 45979 | C4: CUST-0033 | D4: PRD-0034 | E4: EMP-021 | F4: 1 | G4: 0.05 | H4: Same Day | I4: Net Banking | J4: Delivered
A5: ORD-100004 | B5: 46101 | C5: CUST-0353 | D5: PRD-0080 | E5: EMP-004 | F5: 11 | G5: 0.05 | H5: Standard | I5: COD | J5: Delivered
A6: ORD-100005 | B6: 45669 | C6: CUST-0286 | D6: PRD-0079 | E6: EMP-002 | F6: 11 | G6: 0.03 | H6: Standard | I6: COD | J6: Cancelled
A7: ORD-100006 | B7: 46161 | C7: CUST-0085 | D7: PRD-0010 | E7: EMP-025 | F7: 6 | G7: 0.05 | H7: Standard | I7: Net Banking | J7: Delivered
A8: ORD-100007 | B8: 46045 | C8: CUST-0115 | D8: PRD-0071 | E8: EMP-021 | F8: 7 | G8: 0.05 | H8: Standard | I8: COD | J8: Processing
A9: ORD-100008 | B9: 46115 | C9: CUST-0230 | D9: PRD-0012 | E9: EMP-016 | F9: 6 | G9: 0 | H9: Same Day | I9: UPI | J9: Delivered
A10: ORD-100009 | B10: 45658 | C10: CUST-0212 | D10: PRD-0005 | E10: EMP-018 | F10: 2 | G10: 0.08 | H10: Express | I10: Card | J10: Delivered
A11: ORD-100010 | B11: 45713 | C11: CUST-0234 | D11: PRD-0044 | E11: EMP-012 | F11: 4 | G11: 0.2 | H11: Standard | I11: COD | J11: Shipped
A12: ORD-100011 | B12: 45757 | C12: CUST-0187 | D12: PRD-0058 | E12: EMP-004 | F12: 11 | G12: 0.05 | H12: Standard | I12: Net Banking | J12: Processing
A13: ORD-100012 | B13: 46192 | C13: CUST-0410 | D13: PRD-0038 | E13: EMP-018 | F13: 6 | G13: 0 | H13: Standard | I13: Card | J13: Delivered
... A1601: ORD-101600 | B1601: 45986 | C1601: CUST-0418 | D1601: PRD-0074 | E1601: EMP-019 | F1601: 2 | G1601: 0.2 | H1601: Standard | I1601: Card | J1601: Returned

Sheet Sheet1
A1: RollNO | B1: Name | C1: Phone | D1: Unit Price | F1: Quantity | G1: Total Price
A2: 123456 | B2: A | C2: 12345496 | D2: 456 | F2: 5 | G2: =PRODUCT(D2,F2) -> 2280
A3: 452396 | B3: B | C3: 31238556 | D3: 420 | F3: 6 | G3: =PRODUCT(D3,F3) -> 2520
A4: 4843210 | B4: C | C4: 124565 | D4: 782 | F4: 8 | G4: =PRODUCT(D4,F4) -> 6256
A5: 74842 | B5: D | C5: 45646231 | D5: 852 | F5: 7 | G5: =PRODUCT(D5,F5) -> 5964
H6: A | I6: B | J6: C | K6: D
G7: 1
A8: Types of Cell References: | G8: 2
A9: 1. Relative Reference | G9: 3
A10: Absolute Reference | G10: 4
A11: Mixed Reference | G11: 5
A14: 1. Relative Reference
A15: It changes automatically when a formula is copied or filled to another cell
A16: The reference adjust relative to the position of the formula
C17: Business Usecase
C18: Revenue Calculation(Unit Price* Quantity)
C19: Profit Calculation
C20: Discount Calculation
C21: Tax calculation
C22: Commission Calculation
C23: Row by row classifications
A24: 2. Absolute Cell Reference
A25: An absolute reference remains fixed when a formula is copied to another cell
B26: The tax from now is | D26: 0.18
B27: Orders | C27: Tax | D27: Tax amount
C28: 0.18 | F28: 456 | G28: 785 | H28: 79
B29: 456 | C29: 0.12 | D29: =B29*$C$28 -> 82.08 | E29: 0.18 | F29: 0.12 | G29: 0.12 | H29: 0.24
B30: 785 | C30: 0.12 | D30: =B30*$C$28 -> 141.3 | F30: =F28*$E29 -> 82.08 | G30: =G28*$E29 -> 141.3 | H30: =H28*$E29 -> 14.22
B31: 79 | C31: 0.24 | D31: =B31*$C$28 -> 14.22
B32: 782 | C32: 0.12 | D32: =B32*$C$28 -> 140.76
B33: 1325 | C33: 0.04 | D33: =B33*$C$28 -> 238.5
B34: 7855 | C34: 0.09 | D34: =B34*$C$28 -> 1413.9
B36: The "$" before a alphabet(A,B,..)--> our Column is locked in the same way if the "$" sign is after the Numeric row value(1,2,3,4..)
B37: Our row is locked
B38: Partial cell referecing/mixed cell referencing simply means either row is fixed(locked) or column is fixed(locked)
B40: Uses:
B41: Two-dimensional lookup matrics
B42: Financial Models
B43: Sales forecasting
B44: Price volume metrics
...

Sheet Product_Master
A1: Product ID | B1: Product Name | C1: Category | D1: Sub-Category | E1: Brand | F1: Unit Price | G1: Cost Price | H1: Supplier ID | I1: Stock Quantity | J1: Reorder Level
A2: PRD-0001 | B2: Wireless Mouse Pro | C2: Electronics | D2: Accessories | E2: Logitech | F2: 1530.71 | G2: 970.1 | H2: SUP-001 | I2: 379 | J2: 25
A3: PRD-0002 | B3: Mechanical Keyboard | C3: Electronics | D3: Accessories | E3: Keychron | F3: 6926.15 | G3: 4849 | H3: SUP-005 | I3: 377 | J3: 15
A4: PRD-0003 | B4: Business Laptop 14 | C4: Electronics | D4: Computers | E4: Lenovo | F4: 66567.81 | G4: 53767.14 | H4: SUP-018 | I4: 44 | J4: 40
A5: PRD-0004 | B5: Ultrabook 13 | C5: Electronics | D5: Computers | E5: Dell | F5: 79295.54 | G5: 64742.12 | H5: SUP-001 | I5: 47 | J5: 20
A6: PRD-0005 | B6: 27-inch Monitor | C6: Electronics | D6: Displays | E6: Samsung | F6: 22737.11 | G6: 17597.31 | H6: SUP-001 | I6: 287 | J6: 20
A7: PRD-0006 | B7: 24-inch Monitor | C7: Electronics | D7: Displays | E7: LG | F7: 16435.48 | G7: 12430.11 | H7: SUP-018 | I7: 214 | J7: 20
A8: PRD-0007 | B8: USB-C Dock | C8: Electronics | D8: Accessories | E8: Dell | F8: 12070.23 | G8: 8651.06 | H8: SUP-009 | I8: 414 | J8: 15
A9: PRD-0008 | B9: Noise Cancelling Headphones | C9: Electronics | D9: Audio | E9: Sony | F9: 25766.58 | G9: 20098.74 | H9: SUP-006 | I9: 357 | J9: 30
A10: PRD-0009 | B10: Webcam HD | C10: Electronics | D10: Accessories | E10: Logitech | F10: 5982.32 | G10: 3889.16 | H10: SUP-005 | I10: 110 | J10: 25
A11: PRD-0010 | B11: External SSD 1TB | C11: Electronics | D11: Storage | E11: Samsung | F11: 8802.61 | G11: 6651.6 | H11: SUP-013 | I11: 49 | J11: 25
A12: PRD-0011 | B12: Office Chair Ergo | C12: Furniture | D12: Chairs | E12: GreenSoul | F12: 19717.15 | G12: 13698.95 | H12: SUP-009 | I12: 413 | J12: 15
A13: PRD-0012 | B13: Executive Chair | C13: Furniture | D13: Chairs | E13: Featherlite | F13: 28793.57 | G13: 20361.9 | H13: SUP-018 | I13: 63 | J13: 30
... A81: PRD-0080 | B81: Managed Switch 24-Port V4 | C81: Networking | D81: Switches | E81: Cisco | F81: 40479.67 | G81: 30422.01 | H81: SUP-017 | I81: 161 | J81: 25

Sheet VLOOKUP
A1: Product ID | B1: Product_Name
A2: PRD-0001 | B2: =VLOOKUP(A2,Product_Master!$A$1:$J$81,2,FALSE) -> Wireless Mouse Pro
A3: PRD-0002 | B3: =VLOOKUP(A3,Product_Master!$A$1:$J$81,2,FALSE) -> Mechanical Keyboard
A4: PRD-0003 | B4: =VLOOKUP(A4,Product_Master!$A$1:$J$81,2,FALSE) -> Business Laptop 14
A5: PRD-0004 | B5: =VLOOKUP(A5,Product_Master!$A$1:$J$81,2,FALSE) -> Ultrabook 13
A6: PRD-0005 | B6: =VLOOKUP(A6,Product_Master!$A$1:$J$81,2,FALSE) -> 27-inch Monitor
A7: PRD-0006 | B7: =VLOOKUP(A7,Product_Master!$A$1:$J$81,2,FALSE) -> 24-inch Monitor
A8: PRD-0007 | B8: =VLOOKUP(A8,Product_Master!$A$1:$J$81,2,FALSE) -> USB-C Dock
A9: PRD-0008 | B9: =VLOOKUP(A9,Product_Master!$A$1:$J$81,2,FALSE) -> Noise Cancelling Headphones
A10: PRD-0009 | B10: =VLOOKUP(A10,Product_Master!$A$1:$J$81,2,FALSE) -> Webcam HD
A11: PRD-0010 | B11: =VLOOKUP(A11,Product_Master!$A$1:$J$81,2,FALSE) -> External SSD 1TB
A12: PRD-0011 | B12: =VLOOKUP(A12,Product_Master!$A$1:$J$81,2,FALSE) -> Office Chair Ergo
A13: PRD-0012 | B13: =VLOOKUP(A13,Product_Master!$A$1:$J$81,2,FALSE) -> Executive Chair
... A81: PRD-0080 | B81: =VLOOKUP(A81,Product_Master!$A$1:$J$81,2,FALSE) -> Managed Switch 24-Port V4

Sheet Customer_Master
A1: Customer ID | B1: Customer Name | C1: Customer Segment | D1: City | E1: State | F1: Region | G1: Registration Date | H1: Credit Limit | I1: Loyalty Tier | J1: Account Status
A2: CUST-0001 | B2: Akash Agarwal | C2: Consumer | D2: Ahmedabad | E2: Gujarat | F2: West | G2: 45372 | H2: 100000 | I2: Gold | J2: Active
A3: CUST-0002 | B3: Mohit Gupta | C3: Consumer | D3: Hyderabad | E3: Telangana | F3: South | G3: 45834 | H3: 500000 | I3: Platinum | J3: Active
A4: CUST-0003 | B4: Meera Yadav | C4: Consumer | D4: Ahmedabad | E4: Gujarat | F4: West | G4: 45276 | H4: 50000 | I4: Gold | J4: Active
A5: CUST-0004 | B5: Neha Rao | C5: SME | D5: Pune | E5: Maharashtra | F5: West | G5: 45814 | H5: 750000 | I5: Silver | J5: Active
A6: CUST-0005 | B6: Karan Singh | C6: SME | D6: Indore | E6: Madhya Pradesh | F6: Central | G6: 44837 | H6: 150000 | I6: Bronze | J6: Active
A7: CUST-0006 | B7: Sai Yadav | C7: Consumer | D7: Indore | E7: Madhya Pradesh | F7: Central | G7: 44993 | H7: 750000 | I7: Bronze | J7: Active
A8: CUST-0007 | B8: Meera Tiwari | C8: Consumer | D8: Bengaluru | E8: Karnataka | F8: South | G8: 44666 | H8: 50000 | I8: Silver | J8: Active
A9: CUST-0008 | B9: Aarav Agarwal | C9: SME | D9: Lucknow | E9: Uttar Pradesh | F9: North | G9: 45866 | H9: 150000 | I9: Bronze | J9: Active
A10: CUST-0009 | B10: Pooja Sharma | C10: Consumer | D10: Patna | E10: Bihar | F10: East | G10: 45977 | H10: 100000 | I10: Silver | J10: Active
A11: CUST-0010 | B11: Pooja Patel | C11: Consumer | D11: Nagpur | E11: Maharashtra | F11: Central | G11: 44647 | H11: 150000 | I11: Silver | J11: Inactive
A12: CUST-0011 | B12: Sanjay Kapoor | C12: Consumer | D12: Lucknow | E12: Uttar Pradesh | F12: North | G12: 45073 | H12: 750000 | I12: Bronze | J12: Active
A13: CUST-0012 | B13: Simran Patel | C13: SME | D13: Patna | E13: Bihar | F13: East | G13: 45046 | H13: 100000 | I13: Platinum | J13: Active
... A421: CUST-0420 | B421: Aditya Agarwal | C421: Consumer | D421: Chandigarh | E421: Chandigarh | F421: North | G421: 45330 | H421: 100000 | I421: Gold | J421: Active

Sheet Employee_Master
A1: Salesperson ID | B1: Salesperson Name | C1: Department | D1: Region | E1: Joining Date | F1: Manager Name | G1: Monthly Salary | H1: Performance Rating | I1: Employment Status
A2: EMP-001 | B2: Sanjay Gupta | C2: Sales | D2: North | E2: 44485 | F2: Anjali Mehta | G2: 80000 | H2: 5 | I2: Active
A3: EMP-002 | B3: Deepak Sharma | C3: Sales | D3: South | E3: 44867 | F3: Rajiv Khanna | G3: 85000 | H3: 2.9 | I3: Active
A4: EMP-003 | B4: Ishaan Verma | C4: Sales | D4: East | E4: 43515 | F4: Priya Nair | G4: 60000 | H4: 3 | I4: Active
A5: EMP-004 | B5: Deepak Rao | C5: Sales | D5: West | E5: 45313 | F5: Vikram Sethi | G5: 55000 | H5: 4.2 | I5: Active
A6: EMP-005 | B6: Arjun Verma | C6: Sales | D6: Central | E6: 44710 | F6: Sneha Iyer | G6: 80000 | H6: 3.9 | I6: Active
A7: EMP-006 | B7: Vivaan Kapoor | C7: Sales | D7: North | E7: 43116 | F7: Anjali Mehta | G7: 65000 | H7: 2.7 | I7: Active
A8: EMP-007 | B8: Shivam Tiwari | C8: Sales | D8: South | E8: 43918 | F8: Rajiv Khanna | G8: 40000 | H8: 2.6 | I8: Active
A9: EMP-008 | B9: Karan Gupta | C9: Sales | D9: East | E9: 45040 | F9: Priya Nair | G9: 40000 | H9: 3.3 | I9: Active
A10: EMP-009 | B10: Kavya Yadav | C10: Sales | D10: West | E10: 43474 | F10: Vikram Sethi | G10: 85000 | H10: 3.9 | I10: Active
A11: EMP-010 | B11: Sanjay Sinha | C11: Sales | D11: Central | E11: 44614 | F11: Sneha Iyer | G11: 45000 | H11: 3.6 | I11: Active
A12: EMP-011 | B12: Neha Yadav | C12: Sales | D12: North | E12: 44027 | F12: Anjali Mehta | G12: 55000 | H12: 3.9 | I12: Active
A13: EMP-012 | B13: Deepak Singh | C13: Sales | D13: South | E13: 43452 | F13: Rajiv Khanna | G13: 85000 | H13: 3.4 | I13: Active
... A26: EMP-025 | B26: Simran Sinha | C26: Sales | D26: Central | E26: 43259 | F26: Sneha Iyer | G26: 65000 | H26: 4.7 | I26: Active
F29: find the salary which is disbursed to most of the employees
G30: =MATCH(MODE(G2:G26),G2:G26,0) -> 1 | H30: =MATCH(80000,G2:G26,0) -> 1
G31: =MODE(G2:G26) -> 80000
G32: =INDEX(G2:G26,MATCH(MODE(G2:G26),G2:G26)) -> 80000

Sheet Monthly_Targets
A1: Metric | B1: Jan | C1: Feb | D1: Mar | E1: Apr | F1: May | G1: Jun | H1: Jul | I1: Aug | J1: Sep | K1: Oct | L1: Nov | M1: Dec
A2: EMP-001 | B2: 550000 | C2: 596000 | D2: 595000 | E2: 617000 | F2: 629000 | G2: 677000 | H2: 656000 | I2: 710000 | J2: 725000 | K2: 727000 | L2: 763000 | M2: 721000
A3: EMP-002 | B3: 673000 | C3: 645000 | D3: 692000 | E3: 663000 | F3: 690000 | G3: 724000 | H3: 703000 | I3: 720000 | J3: 786000 | K3: 795000 | L3: 812000 | M3: 836000
A4: EMP-003 | B4: 432000 | C4: 423000 | D4: 442000 | E4: 464000 | F4: 454000 | G4: 504000 | H4: 516000 | I4: 480000 | J4: 499000 | K4: 545000 | L4: 556000 | M4: 534000
A5: EMP-004 | B5: 717000 | C5: 766000 | D5: 769000 | E5: 805000 | F5: 833000 | G5: 845000 | H5: 915000 | I5: 910000 | J5: 886000 | K5: 929000 | L5: 943000 | M5: 1012000
A6: EMP-005 | B6: 795000 | C6: 791000 | D6: 791000 | E6: 884000 | F6: 889000 | G6: 903000 | H6: 881000 | I6: 911000 | J6: 908000 | K6: 968000 | L6: 1027000 | M6: 1036000
A7: EMP-006 | B7: 881000 | C7: 902000 | D7: 976000 | E7: 983000 | F7: 1046000 | G7: 1081000 | H7: 1070000 | I7: 1068000 | J7: 1050000 | K7: 1078000 | L7: 1174000 | M7: 1129000
A8: EMP-007 | B8: 923000 | C8: 888000 | D8: 985000 | E8: 970000 | F8: 967000 | G8: 983000 | H8: 1002000 | I8: 1013000 | J8: 1059000 | K8: 1105000 | L8: 1144000 | M8: 1117000
A9: EMP-008 | B9: 452000 | C9: 525000 | D9: 535000 | E9: 539000 | F9: 533000 | G9: 547000 | H9: 540000 | I9: 577000 | J9: 576000 | K9: 579000 | L9: 587000 | M9: 602000
A10: EMP-009 | B10: 590000 | C10: 640000 | D10: 670000 | E10: 638000 | F10: 642000 | G10: 705000 | H10: 730000 | I10: 738000 | J10: 753000 | K10: 752000 | L10: 772000 | M10: 788000
A11: EMP-010 | B11: 414000 | C11: 442000 | D11: 413000 | E11: 432000 | F11: 440000 | G11: 432000 | H11: 477000 | I11: 480000 | J11: 470000 | K11: 508000 | L11: 492000 | M11: 518000
A12: EMP-011 | B12: 828000 | C12: 823000 | D12: 826000 | E12: 880000 | F12: 898000 | G12: 921000 | H12: 871000 | I12: 882000 | J12: 904000 | K12: 937000 | L12: 1011000 | M12: 1026000
A13: EMP-012 | B13: 563000 | C13: 573000 | D13: 570000 | E13: 553000 | F13: 566000 | G13: 624000 | H13: 606000 | I13: 651000 | J13: 629000 | K13: 657000 | L13: 662000 | M13: 651000
... A26: EMP-025 | B26: 507000 | C26: 539000 | D26: 556000 | E26: 595000 | F26: 598000 | G26: 597000 | H26: 606000 | I26: 651000 | J26: 615000 | K26: 626000 | L26: 680000 | M26: 710000
C29: Find the monthly target sales in march for employee EMP-005 | H29: It is used when Hlookup fails
C30: =INDEX(B2:E26,MATCH("EMP-005",A2:A26,0),MATCH("Mar",B1:D1,0)) -> 791000 | D30: =INDEX(B2:D26,5,3) -> 791000
B31: Row number | C31: =MATCH("EMP-005",A2:A26,0) -> 5
B32: Column number | C32: =MATCH("Mar",B1:D1,) -> 3
C34: Find the monthly target sales in July for employee EMP-016
C35: =INDEX(B2:H26,MATCH("EMP-016",A2:A26,0),MATCH("Jul",B1:H1,0)) -> 468000
C37: Find the monthly target sales in Aug for employee EMP-019
C38: =INDEX(B2:I26,MATCH("EMP-019",A2:A26,0),MATCH("Aug",B1:I1,0)) -> 1025000
