Workbook

Sheet Customer
A1: Customer ID | B1: Customer Name | C1: Customer Segment | D1: City | E1: State | F1: Region | G1: Registration Date | H1: Total Price | I1: Loyalty Tier | J1: Account Status | K1: Quantity | L1: Unit Price
A2: CUST-0001 | B2: Akash Agarwal | C2: Consumer | D2: Ahmedabad | E2: Gujarat | F2: West | G2: 45372 | H2: 100000 | I2: Gold | J2: Active | K2: 2 | L2: =H2/K2 -> 50000 | M2: =IF(K2=0,"Check the Denominator",H2/K2) -> 50000 | N2: =IFERROR(H2/K2,"Denominator Zero") -> 50000
A3: CUST-0002 | B3: Mohit Gupta | C3: Consumer | D3: Hyderabad | E3: Telangana | F3: South | G3: 45834 | H3: 500000 | I3: Platinum | J3: Active | K3: 1 | L3: =H3/K3 -> 500000 | M3: =IF(K3=0,"Check the Denominator",H3/K3) -> 500000 | N3: =IFERROR(H3/K3,"Denominator Zero") -> 500000
A4: CUST-0003 | B4: Meera Yadav | C4: Consumer | D4: Ahmedabad | E4: Gujarat | F4: West | G4: 45276 | H4: 50000 | I4: Gold | J4: Active | K4: 1 | L4: =H4/K4 -> 50000 | M4: =IF(K4=0,"Check the Denominator",H4/K4) -> 50000 | N4: =IFERROR(H4/K4,"Denominator Zero") -> 50000
A5: CUST-0004 | B5: Neha Rao | C5: SME | D5: Pune | E5: Maharashtra | F5: West | G5: 45814 | H5: 750000 | I5: Silver | J5: Active | K5: 5 | L5: =H5/K5 -> 150000 | M5: =IF(K5=0,"Check the Denominator",H5/K5) -> 150000 | N5: =IFERROR(H5/K5,"Denominator Zero") -> 150000
A6: CUST-0005 | B6: Karan Singh | C6: SME | D6: Indore | E6: Madhya Pradesh | F6: Central | G6: 44837 | H6: 150000 | I6: Bronze | J6: Active | K6: 4 | L6: =H6/K6 -> 37500 | M6: =IF(K6=0,"Check the Denominator",H6/K6) -> 37500 | N6: =IFERROR(H6/K6,"Denominator Zero") -> 37500
A7: CUST-0006 | B7: Sai Yadav | C7: Consumer | D7: Indore | E7: Madhya Pradesh | F7: Central | G7: 44993 | H7: 750000 | I7: Bronze | J7: Active | K7: 0 | L7: =H7/K7 -> #DIV/0! | M7: =IF(K7=0,"Check the Denominator",H7/K7) -> Check the Denominator | N7: =IFERROR(H7/K7,"Denominator Zero") -> Denominator Zero
A8: CUST-0007 | B8: Meera Tiwari | C8: Consumer | D8: Bengaluru | E8: Karnataka | F8: South | G8: 44666 | H8: 50000 | I8: Silver | J8: Active | K8: 5 | L8: =H8/K8 -> 10000 | M8: =IF(K8=0,"Check the Denominator",H8/K8) -> 10000 | N8: =IFERROR(H8/K8,"Denominator Zero") -> 10000
A9: CUST-0008 | B9: Aarav Agarwal | C9: SME | D9: Lucknow | E9: Uttar Pradesh | F9: North | G9: 45866 | H9: 150000 | I9: Bronze | J9: Active | K9: 5 | L9: =H9/K9 -> 30000 | M9: =IF(K9=0,"Check the Denominator",H9/K9) -> 30000 | N9: =IFERROR(H9/K9,"Denominator Zero") -> 30000
A10: CUST-0009 | B10: Pooja Sharma | C10: Consumer | D10: Patna | E10: Bihar | F10: East | G10: 45977 | H10: 100000 | I10: Silver | J10: Active | K10: 0 | L10: =H10/K10 -> #DIV/0! | M10: =IF(K10=0,"Check the Denominator",H10/K10) -> Check the Denominator | N10: =IFERROR(H10/K10,"Denominator Zero") -> Denominator Zero
A11: CUST-0010 | B11: Pooja Patel | C11: Consumer | D11: Nagpur | E11: Maharashtra | F11: Central | G11: 44647 | H11: 150000 | I11: Silver | J11: Inactive | K11: 0 | L11: =H11/K11 -> #DIV/0! | M11: =IF(K11=0,"Check the Denominator",H11/K11) -> Check the Denominator | N11: =IFERROR(H11/K11,"Denominator Zero") -> Denominator Zero
A12: CUST-0011 | B12: Sanjay Kapoor | C12: Consumer | D12: Lucknow | E12: Uttar Pradesh | F12: North | G12: 45073 | H12: 750000 | I12: Bronze | J12: Active | K12: 4 | L12: =H12/K12 -> 187500 | M12: =IF(K12=0,"Check the Denominator",H12/K12) -> 187500 | N12: =IFERROR(H12/K12,"Denominator Zero") -> 187500
A13: CUST-0012 | B13: Simran Patel | C13: SME | D13: Patna | E13: Bihar | F13: East | G13: 45046 | H13: 100000 | I13: Platinum | J13: Active | K13: 0 | L13: =H13/K13 -> #DIV/0! | M13: =IF(K13=0,"Check the Denominator",H13/K13) -> Check the Denominator | N13: =IFERROR(H13/K13,"Denominator Zero") -> Denominator Zero
A14: CUST-0013 | B14: Aarav Jain | C14: SME | D14: Patna | E14: Bihar | F14: East | G14: 45242 | H14: 250000 | I14: Gold | J14: Active
A15: CUST-0014 | B15: Rahul Jain | C15: SME | D15: Surat | E15: Gujarat | F15: West | G15: 44783 | H15: 250000 | I15: Gold | J15: Active
A16: CUST-0015 | B16: Kabir Malhotra | C16: Consumer | D16: Surat | E16: Gujarat | F16: West | G16: 45028 | H16: 100000 | I16: Bronze | J16: Active
A17: CUST-0016 | B17: Rahul Gupta | C17: SME | D17: Hyderabad | E17: Telangana | F17: South | G17: 45133 | H17: 150000 | I17: Silver | J17: Active
A18: CUST-0017 | B18: Nisha Sharma | C18: Consumer | D18: Indore | E18: Madhya Pradesh | F18: Central | G18: 45096 | H18: 100000 | I18: Silver | J18: Inactive
A19: CUST-0018 | B19: Arjun Pandey | C19: Consumer | D19: Lucknow | E19: Uttar Pradesh | F19: North | G19: 45204 | H19: 250000 | I19: Silver | J19: Active
A20: CUST-0019 | B20: Sanjay Kumar | C20: Consumer | D20: Kolkata | E20: West Bengal | F20: East | G20: 46013 | H20: 250000 | I20: Bronze | J20: Inactive
A21: CUST-0020 | B21: Akash Kumar | C21: Consumer | D21: Indore | E21: Madhya Pradesh | F21: Central | G21: 44705 | H21: 750000 | I21: Platinum | J21: Active
A22: CUST-0021 | B22: Rohit Saxena | C22: Corporate | D22: Chandigarh | E22: Chandigarh | F22: North | G22: 45927 | H22: 250000 | I22: Bronze | J22: Active
A23: CUST-0022 | B23: Sai Kumar | C23: Consumer | D23: Indore | E23: Madhya Pradesh | F23: Central | G23: 45338 | H23: 750000 | I23: Gold | J23: Active
A24: CUST-0023 | B24: Karan Sinha | C24: Corporate | D24: Nagpur | E24: Maharashtra | F24: Central | G24: 44562 | H24: 150000 | I24: Bronze | J24: Active
A25: CUST-0024 | B25: Simran Agarwal | C25: Corporate | D25: Nagpur | E25: Maharashtra | F25: Central | G25: 45467 | H25: 750000 | I25: Bronze | J25: Active
... A35: CUST-0034 | B35: Aditya Patel | C35: Consumer | D35: Indore | E35: Madhya Pradesh | F35: Central | G35: 45346 | H35: 750000 | I35: Bronze | J35: Active

Sheet Data Validation
D1: DATA VALIDATION
A2: It prevents the invalid entry, but can't apply to the entries which are made previously bfore applying our validation
A3: It standarsize the datasets
A4: Improves the reporting accuracy
A5: Customer ID | B5: Customer Name | C5: Customer Segment | D5: City | E5: State | F5: Region | G5: Registration Date | H5: AGE | I5: Total Price | J5: Phone Number | K5: Loyalty Tier | L5: Entry Time
A6: CUST-0001 | B6: Akash Agarwal | C6: Consumer | D6: Ahmedabad | E6: Gujarat | F6: West | G6: 45372 | H6: 18 | I6: 466 | J6: 1234567890 | K6: Gold | L6: 0.58333333
A7: CUST-0002 | B7: Mohit Gupta | C7: Consumer | D7: Hyderabad | E7: Telangana | F7: South | G7: 45834 | H7: 18 | I7: 500000 | K7: Platinum | M7: Enter the Age in the customers table and make sure it is in whole number
A8: CUST-0003 | B8: Meera Yadav | C8: Consumer | D8: Ahmedabad | E8: Gujarat | F8: West | G8: 45276 | H8: 18 | I8: 50000 | K8: Gold
A9: CUST-0004 | B9: Neha Rao | C9: SME | D9: Pune | E9: Maharashtra | F9: West | G9: 45814 | H9: 18 | I9: 750000 | K9: Silver
A10: CUST-0005 | B10: Karan Singh | C10: SME | D10: Indore | E10: Madhya Pradesh | F10: Central | G10: 44837 | H10: 18 | I10: 150000 | K10: Bronze
A11: CUST-0006 | B11: Sai Yadav | C11: Consumer | D11: Indore | E11: Madhya Pradesh | F11: Central | G11: 44993 | H11: 18 | I11: 750000 | K11: Bronze | M11: Gold
A12: CUST-0007 | B12: Meera Tiwari | C12: Consumer | D12: Bengaluru | E12: Karnataka | F12: South | G12: 44666 | H12: 18 | I12: 50000 | K12: Silver | M12: Platinum
A13: CUST-0008 | B13: Aarav Agarwal | C13: SME | D13: Lucknow | E13: Uttar Pradesh | F13: North | G13: 45866 | H13: 18 | I13: 150000 | K13: Bronze | M13: Silver
A14: CUST-0009 | B14: Pooja Sharma | C14: Consumer | D14: Patna | E14: Bihar | F14: East | G14: 45977 | H14: 18 | I14: 100000 | K14: Silver | M14: Bronze
A15: CUST-0010 | B15: Pooja Patel | C15: Consumer | D15: Nagpur | E15: Maharashtra | F15: Central | G15: 44647 | H15: 18 | I15: 150000 | K15: Silver
A16: CUST-0011 | B16: Sanjay Kapoor | C16: Consumer | D16: Lucknow | E16: Uttar Pradesh | F16: North | G16: 45073 | H16: 18 | I16: 750000 | K16: Bronze | M16: West
A17: CUST-0012 | B17: Simran Patel | C17: SME | D17: Patna | E17: Bihar | F17: East | G17: 45046 | H17: 18 | I17: 100000 | K17: Platinum | M17: South
A18: CUST-0013 | B18: Aarav Jain | C18: SME | D18: Patna | E18: Bihar | F18: East | G18: 45242 | H18: 18 | I18: 250000 | K18: Gold | M18: Central
A19: CUST-0014 | B19: Rahul Jain | C19: SME | D19: Surat | E19: Gujarat | F19: West | G19: 44783 | H19: 60 | I19: 250000 | K19: Gold | M19: East
A20: CUST-0015 | B20: Kabir Malhotra | C20: Consumer | D20: Surat | E20: Gujarat | F20: West | G20: 45028 | H20: 25 | I20: 100000 | K20: Bronze | M20: North
A21: CUST-0016 | B21: Rahul Gupta | C21: SME | D21: Hyderabad | E21: Telangana | F21: South | G21: 45133 | H21: 18 | I21: 150000 | K21: Silver
A22: CUST-0017 | B22: Nisha Sharma | C22: Consumer | D22: Indore | E22: Madhya Pradesh | F22: Central | G22: 45096 | I22: 100000 | K22: Silver
A23: CUST-0018 | B23: Arjun Pandey | C23: Consumer | D23: Lucknow | E23: Uttar Pradesh | F23: North | G23: 45204 | I23: 250000 | K23: Silver
A24: CUST-0019 | B24: Sanjay Kumar | C24: Consumer | D24: Kolkata | E24: West Bengal | F24: East | G24: 46013 | I24: 250000 | K24: Bronze
A25: CUST-0020 | B25: Akash Kumar | C25: Consumer | D25: Indore | E25: Madhya Pradesh | F25: Central | G25: 44705 | I25: 750000 | K25: Platinum
A26: CUST-0021 | B26: Rohit Saxena | C26: Corporate | D26: Chandigarh | E26: Chandigarh | F26: North | G26: 45927 | I26: 250000 | K26: Bronze
A27: CUST-0022 | B27: Sai Kumar | C27: Consumer | D27: Indore | E27: Madhya Pradesh | F27: Central | G27: 45338 | I27: 750000 | K27: Gold
A28: CUST-0023 | B28: Karan Sinha | C28: Corporate | D28: Nagpur | E28: Maharashtra | F28: Central | G28: 44562 | I28: 150000 | K28: Bronze
A29: CUST-0024 | B29: Simran Agarwal | C29: Corporate | D29: Nagpur | E29: Maharashtra | F29: Central | G29: 45467 | I29: 750000 | K29: Bronze
A30: CUST-0025 | B30: Akash Gupta | C30: Consumer | D30: Pune | E30: Maharashtra | F30: West | G30: 45921 | I30: 750000 | K30: Silver
A31: CUST-0026 | B31: Akash Saxena | C31: Consumer | D31: Surat | E31: Gujarat | F31: West | G31: 44969 | I31: 100000 | K31: Bronze
A32: CUST-0027 | B32: Simran Gupta | C32: Corporate | D32: Guwahati | E32: Assam | F32: East | G32: 45851 | I32: 500000 | K32: Bronze
A33: CUST-0028 | B33: Riya Mishra | C33: Consumer | D33: Guwahati | E33: Assam | F33: East | G33: 45970 | I33: 50000 | K33: Gold
... A39: CUST-0034 | B39: Aditya Patel | C39: Consumer | D39: Indore | E39: Madhya Pradesh | F39: Central | G39: 45346 | I39: 750000 | K39: Bronze

Sheet Errors
D1: Common Erros in Excel
C2: Error Handling
C4: 1. #N/A Error
C5: This error in excel means it cannot find the value you're looking for/asking for.
C6: It's like searching an emp_id but it doesn’t exist in employee's record
C8: We use IFNA Function to handle these #N/A errors
C9: Example: We want to find or lookup a value againsy "CUST-0035" that doesn't exist in data.
C10: Syntax: IFNA(value,value if na)
A11: Normal Lookup Function | C11: =VLOOKUP("CUST-0035",Customer!$A$2:$J$35,2,FALSE) -> #N/A | D11: =_xlfn.XLOOKUP("CUST-0035",Customer!A2:A35,Customer!B2:B35,"Customer ID not available") -> Customer ID not available
B12: Fixing with | C12: =_xlfn.IFNA(VLOOKUP("CUST-0035",Customer!$A$2:$J$35,2,FALSE),"Check customer ID") -> Check customer ID
C13: If a customer is missing, so what our report will show? Now it will show the correct error we have entered.
B14: Error
C15: 2. #VALUE! Error
C16: It happens when Excel gets the wrong data type, Like trying to add text with numbers.
C17: Example: | D17: "Mobile"+ 2500
C18: Usecase: It is mainly used for the values stored as a text when we used to import CSV files
C19: 2600 | D19: 2500
C20: =VALUE(C19) -> 2600
C21: Value Function returns the given text value as a nu,merical value
E22: =SUM(VALUE(C19),D19) -> 5100
D23: sh | E23: 452 | F23: =SUM(D23+E23) -> #VALUE! | G23: =IFERROR(SUM(D23+E23),"Wrong data type") -> Wrong data type
C24: 3. #REF! Error
C25: It indicates that our reference is wrong. It happens when the cell we are pointing is deleted
C27: 4. #DIV/0! Error | D27: =TRIM(D26)
C28: It tells us that for some reason the denominator is 0
B29: Total price | C29: 5632
B30: Quantity | C30: 0
C31: Unit price | D31: =C29/C30 -> #DIV/0!
C33: If the denominator value is 0 then tell that "check the Denominator value
C34: In Finance, we don't use 0 to show can't divide by zero or undefined value We can write "N/A"
C36: 5. #NAME? Error
C37: This error happens when we try to type a wrong formula, or spelling mistake in formula
C38: 12
C39: 45
C40: 45
C41: =SUM(C38:C40) -> 102
C42: [=AVERAGE?] | D42: It will also show #NAME? error | G42: {=IFERROR(AVERAGE?,"Formula Spelling Error")} -> Formula Spelling Error
C44: 6. #NUM! Error
C45: It tells that there is invalid numerical calculation. Like asking excel to calculate something that's mathematically Impossible
C46: =-25^(1/2) -> #NUM! | D46: I am asking the Square root of -25
...
